ERROR 2024-03-26 16:05:38,361 exception Invalid HTTP_HOST header: '127.0.0.1:8000'. You may need to add '127.0.0.1' to ALLOWED_HOSTS.
ERROR 2024-03-26 16:05:57,282 exception Invalid HTTP_HOST header: '127.0.0.1:8000'. You may need to add '127.0.0.1' to ALLOWED_HOSTS.
ERROR 2024-03-30 03:35:42,587 log Internal Server Error: /manage/get_action_tries/세종대/
Traceback (most recent call last):
  File "/home/sf/.local/lib/python3.10/site-packages/django/db/models/fields/__init__.py", line 2117, in get_prep_value
    return int(value)
TypeError: int() argument must be a string, a bytes-like object or a real number, not 'builtin_function_or_method'

The above exception was the direct cause of the following exception:

Traceback (most recent call last):
  File "/home/sf/.local/lib/python3.10/site-packages/asgiref/sync.py", line 534, in thread_handler
    raise exc_info[1]
  File "/home/sf/.local/lib/python3.10/site-packages/django/core/handlers/exception.py", line 42, in inner
    response = await get_response(request)
  File "/home/sf/.local/lib/python3.10/site-packages/django/core/handlers/base.py", line 253, in _get_response_async
    response = await wrapped_callback(
  File "/home/sf/.local/lib/python3.10/site-packages/asgiref/sync.py", line 479, in __call__
    ret: _R = await loop.run_in_executor(
  File "/home/sf/.local/lib/python3.10/site-packages/asgiref/current_thread_executor.py", line 40, in run
    result = self.fn(*self.args, **self.kwargs)
  File "/home/sf/.local/lib/python3.10/site-packages/asgiref/sync.py", line 538, in thread_handler
    return func(*args, **kwargs)
  File "/home/sf/sang/Fortuna/FortunaProject/./flag/views.py", line 149, in get_action_tries_for_team
    action_tries = ActionTry.objects.filter(attacker_name=team_name, round=round)
  File "/home/sf/.local/lib/python3.10/site-packages/django/db/models/manager.py", line 87, in manager_method
    return getattr(self.get_queryset(), name)(*args, **kwargs)
  File "/home/sf/.local/lib/python3.10/site-packages/django/db/models/query.py", line 1476, in filter
    return self._filter_or_exclude(False, args, kwargs)
  File "/home/sf/.local/lib/python3.10/site-packages/django/db/models/query.py", line 1494, in _filter_or_exclude
    clone._filter_or_exclude_inplace(negate, args, kwargs)
  File "/home/sf/.local/lib/python3.10/site-packages/django/db/models/query.py", line 1501, in _filter_or_exclude_inplace
    self._query.add_q(Q(*args, **kwargs))
  File "/home/sf/.local/lib/python3.10/site-packages/django/db/models/sql/query.py", line 1613, in add_q
    clause, _ = self._add_q(q_object, self.used_aliases)
  File "/home/sf/.local/lib/python3.10/site-packages/django/db/models/sql/query.py", line 1645, in _add_q
    child_clause, needed_inner = self.build_filter(
  File "/home/sf/.local/lib/python3.10/site-packages/django/db/models/sql/query.py", line 1559, in build_filter
    condition = self.build_lookup(lookups, col, value)
  File "/home/sf/.local/lib/python3.10/site-packages/django/db/models/sql/query.py", line 1389, in build_lookup
    lookup = lookup_class(lhs, rhs)
  File "/home/sf/.local/lib/python3.10/site-packages/django/db/models/lookups.py", line 30, in __init__
    self.rhs = self.get_prep_lookup()
  File "/home/sf/.local/lib/python3.10/site-packages/django/db/models/lookups.py", line 364, in get_prep_lookup
    return super().get_prep_lookup()
  File "/home/sf/.local/lib/python3.10/site-packages/django/db/models/lookups.py", line 88, in get_prep_lookup
    return self.lhs.output_field.get_prep_value(self.rhs)
  File "/home/sf/.local/lib/python3.10/site-packages/django/db/models/fields/__init__.py", line 2119, in get_prep_value
    raise e.__class__(
TypeError: Field 'round' expected a number but got <built-in function round>.
ERROR 2024-03-30 03:36:02,992 log Internal Server Error: /manage/flag/create_flag/
Traceback (most recent call last):
  File "/home/sf/.local/lib/python3.10/site-packages/asgiref/sync.py", line 534, in thread_handler
    raise exc_info[1]
  File "/home/sf/.local/lib/python3.10/site-packages/django/core/handlers/exception.py", line 42, in inner
    response = await get_response(request)
  File "/home/sf/.local/lib/python3.10/site-packages/django/core/handlers/base.py", line 253, in _get_response_async
    response = await wrapped_callback(
  File "/home/sf/.local/lib/python3.10/site-packages/asgiref/sync.py", line 479, in __call__
    ret: _R = await loop.run_in_executor(
  File "/home/sf/.local/lib/python3.10/site-packages/asgiref/current_thread_executor.py", line 40, in run
    result = self.fn(*self.args, **self.kwargs)
  File "/home/sf/.local/lib/python3.10/site-packages/asgiref/sync.py", line 538, in thread_handler
    return func(*args, **kwargs)
  File "/home/sf/sang/Fortuna/FortunaProject/./flag/views.py", line 129, in create_flag_view
    create_flag()  # 플래그 생성
  File "/home/sf/sang/Fortuna/FortunaProject/./flag/views.py", line 121, in create_flag
    flags_created = generate_flag_for_gamebox(gamebox.team_id, gamebox.challenge_id)
  File "/home/sf/sang/Fortuna/FortunaProject/./flag/views.py", line 82, in generate_flag_for_gamebox
    team = Team.objects.get(team_id=team_id)
  File "/home/sf/.local/lib/python3.10/site-packages/django/db/models/manager.py", line 87, in manager_method
    return getattr(self.get_queryset(), name)(*args, **kwargs)
  File "/home/sf/.local/lib/python3.10/site-packages/django/db/models/query.py", line 649, in get
    raise self.model.DoesNotExist(
account.models.Team.DoesNotExist: Team matching query does not exist.
ERROR 2024-03-30 03:36:09,224 log Internal Server Error: /manage/get_action_tries/admin/
Traceback (most recent call last):
  File "/home/sf/.local/lib/python3.10/site-packages/django/db/models/fields/__init__.py", line 2117, in get_prep_value
    return int(value)
TypeError: int() argument must be a string, a bytes-like object or a real number, not 'builtin_function_or_method'

The above exception was the direct cause of the following exception:

Traceback (most recent call last):
  File "/home/sf/.local/lib/python3.10/site-packages/asgiref/sync.py", line 534, in thread_handler
    raise exc_info[1]
  File "/home/sf/.local/lib/python3.10/site-packages/django/core/handlers/exception.py", line 42, in inner
    response = await get_response(request)
  File "/home/sf/.local/lib/python3.10/site-packages/django/core/handlers/base.py", line 253, in _get_response_async
    response = await wrapped_callback(
  File "/home/sf/.local/lib/python3.10/site-packages/asgiref/sync.py", line 479, in __call__
    ret: _R = await loop.run_in_executor(
  File "/home/sf/.local/lib/python3.10/site-packages/asgiref/current_thread_executor.py", line 40, in run
    result = self.fn(*self.args, **self.kwargs)
  File "/home/sf/.local/lib/python3.10/site-packages/asgiref/sync.py", line 538, in thread_handler
    return func(*args, **kwargs)
  File "/home/sf/sang/Fortuna/FortunaProject/./flag/views.py", line 149, in get_action_tries_for_team
    action_tries = ActionTry.objects.filter(attacker_name=team_name, round=round)
  File "/home/sf/.local/lib/python3.10/site-packages/django/db/models/manager.py", line 87, in manager_method
    return getattr(self.get_queryset(), name)(*args, **kwargs)
  File "/home/sf/.local/lib/python3.10/site-packages/django/db/models/query.py", line 1476, in filter
    return self._filter_or_exclude(False, args, kwargs)
  File "/home/sf/.local/lib/python3.10/site-packages/django/db/models/query.py", line 1494, in _filter_or_exclude
    clone._filter_or_exclude_inplace(negate, args, kwargs)
  File "/home/sf/.local/lib/python3.10/site-packages/django/db/models/query.py", line 1501, in _filter_or_exclude_inplace
    self._query.add_q(Q(*args, **kwargs))
  File "/home/sf/.local/lib/python3.10/site-packages/django/db/models/sql/query.py", line 1613, in add_q
    clause, _ = self._add_q(q_object, self.used_aliases)
  File "/home/sf/.local/lib/python3.10/site-packages/django/db/models/sql/query.py", line 1645, in _add_q
    child_clause, needed_inner = self.build_filter(
  File "/home/sf/.local/lib/python3.10/site-packages/django/db/models/sql/query.py", line 1559, in build_filter
    condition = self.build_lookup(lookups, col, value)
  File "/home/sf/.local/lib/python3.10/site-packages/django/db/models/sql/query.py", line 1389, in build_lookup
    lookup = lookup_class(lhs, rhs)
  File "/home/sf/.local/lib/python3.10/site-packages/django/db/models/lookups.py", line 30, in __init__
    self.rhs = self.get_prep_lookup()
  File "/home/sf/.local/lib/python3.10/site-packages/django/db/models/lookups.py", line 364, in get_prep_lookup
    return super().get_prep_lookup()
  File "/home/sf/.local/lib/python3.10/site-packages/django/db/models/lookups.py", line 88, in get_prep_lookup
    return self.lhs.output_field.get_prep_value(self.rhs)
  File "/home/sf/.local/lib/python3.10/site-packages/django/db/models/fields/__init__.py", line 2119, in get_prep_value
    raise e.__class__(
TypeError: Field 'round' expected a number but got <built-in function round>.
ERROR 2024-03-30 03:36:12,151 log Internal Server Error: /manage/get_action_tries/세종대/
Traceback (most recent call last):
  File "/home/sf/.local/lib/python3.10/site-packages/django/db/models/fields/__init__.py", line 2117, in get_prep_value
    return int(value)
TypeError: int() argument must be a string, a bytes-like object or a real number, not 'builtin_function_or_method'

The above exception was the direct cause of the following exception:

Traceback (most recent call last):
  File "/home/sf/.local/lib/python3.10/site-packages/asgiref/sync.py", line 534, in thread_handler
    raise exc_info[1]
  File "/home/sf/.local/lib/python3.10/site-packages/django/core/handlers/exception.py", line 42, in inner
    response = await get_response(request)
  File "/home/sf/.local/lib/python3.10/site-packages/django/core/handlers/base.py", line 253, in _get_response_async
    response = await wrapped_callback(
  File "/home/sf/.local/lib/python3.10/site-packages/asgiref/sync.py", line 479, in __call__
    ret: _R = await loop.run_in_executor(
  File "/home/sf/.local/lib/python3.10/site-packages/asgiref/current_thread_executor.py", line 40, in run
    result = self.fn(*self.args, **self.kwargs)
  File "/home/sf/.local/lib/python3.10/site-packages/asgiref/sync.py", line 538, in thread_handler
    return func(*args, **kwargs)
  File "/home/sf/sang/Fortuna/FortunaProject/./flag/views.py", line 149, in get_action_tries_for_team
    action_tries = ActionTry.objects.filter(attacker_name=team_name, round=round)
  File "/home/sf/.local/lib/python3.10/site-packages/django/db/models/manager.py", line 87, in manager_method
    return getattr(self.get_queryset(), name)(*args, **kwargs)
  File "/home/sf/.local/lib/python3.10/site-packages/django/db/models/query.py", line 1476, in filter
    return self._filter_or_exclude(False, args, kwargs)
  File "/home/sf/.local/lib/python3.10/site-packages/django/db/models/query.py", line 1494, in _filter_or_exclude
    clone._filter_or_exclude_inplace(negate, args, kwargs)
  File "/home/sf/.local/lib/python3.10/site-packages/django/db/models/query.py", line 1501, in _filter_or_exclude_inplace
    self._query.add_q(Q(*args, **kwargs))
  File "/home/sf/.local/lib/python3.10/site-packages/django/db/models/sql/query.py", line 1613, in add_q
    clause, _ = self._add_q(q_object, self.used_aliases)
  File "/home/sf/.local/lib/python3.10/site-packages/django/db/models/sql/query.py", line 1645, in _add_q
    child_clause, needed_inner = self.build_filter(
  File "/home/sf/.local/lib/python3.10/site-packages/django/db/models/sql/query.py", line 1559, in build_filter
    condition = self.build_lookup(lookups, col, value)
  File "/home/sf/.local/lib/python3.10/site-packages/django/db/models/sql/query.py", line 1389, in build_lookup
    lookup = lookup_class(lhs, rhs)
  File "/home/sf/.local/lib/python3.10/site-packages/django/db/models/lookups.py", line 30, in __init__
    self.rhs = self.get_prep_lookup()
  File "/home/sf/.local/lib/python3.10/site-packages/django/db/models/lookups.py", line 364, in get_prep_lookup
    return super().get_prep_lookup()
  File "/home/sf/.local/lib/python3.10/site-packages/django/db/models/lookups.py", line 88, in get_prep_lookup
    return self.lhs.output_field.get_prep_value(self.rhs)
  File "/home/sf/.local/lib/python3.10/site-packages/django/db/models/fields/__init__.py", line 2119, in get_prep_value
    raise e.__class__(
TypeError: Field 'round' expected a number but got <built-in function round>.
ERROR 2024-03-30 08:51:32,055 log Internal Server Error: /manage/get_action_tries/admin/
Traceback (most recent call last):
  File "/home/sf/.local/lib/python3.10/site-packages/django/db/models/fields/__init__.py", line 2117, in get_prep_value
    return int(value)
TypeError: int() argument must be a string, a bytes-like object or a real number, not 'builtin_function_or_method'

The above exception was the direct cause of the following exception:

Traceback (most recent call last):
  File "/home/sf/.local/lib/python3.10/site-packages/asgiref/sync.py", line 534, in thread_handler
    raise exc_info[1]
  File "/home/sf/.local/lib/python3.10/site-packages/django/core/handlers/exception.py", line 42, in inner
    response = await get_response(request)
  File "/home/sf/.local/lib/python3.10/site-packages/django/core/handlers/base.py", line 253, in _get_response_async
    response = await wrapped_callback(
  File "/home/sf/.local/lib/python3.10/site-packages/asgiref/sync.py", line 479, in __call__
    ret: _R = await loop.run_in_executor(
  File "/home/sf/.local/lib/python3.10/site-packages/asgiref/current_thread_executor.py", line 40, in run
    result = self.fn(*self.args, **self.kwargs)
  File "/home/sf/.local/lib/python3.10/site-packages/asgiref/sync.py", line 538, in thread_handler
    return func(*args, **kwargs)
  File "/home/sf/sang/Fortuna/FortunaProject/./flag/views.py", line 149, in get_action_tries_for_team
    action_tries = ActionTry.objects.filter(attacker_name=team_name, round=round)
  File "/home/sf/.local/lib/python3.10/site-packages/django/db/models/manager.py", line 87, in manager_method
    return getattr(self.get_queryset(), name)(*args, **kwargs)
  File "/home/sf/.local/lib/python3.10/site-packages/django/db/models/query.py", line 1476, in filter
    return self._filter_or_exclude(False, args, kwargs)
  File "/home/sf/.local/lib/python3.10/site-packages/django/db/models/query.py", line 1494, in _filter_or_exclude
    clone._filter_or_exclude_inplace(negate, args, kwargs)
  File "/home/sf/.local/lib/python3.10/site-packages/django/db/models/query.py", line 1501, in _filter_or_exclude_inplace
    self._query.add_q(Q(*args, **kwargs))
  File "/home/sf/.local/lib/python3.10/site-packages/django/db/models/sql/query.py", line 1613, in add_q
    clause, _ = self._add_q(q_object, self.used_aliases)
  File "/home/sf/.local/lib/python3.10/site-packages/django/db/models/sql/query.py", line 1645, in _add_q
    child_clause, needed_inner = self.build_filter(
  File "/home/sf/.local/lib/python3.10/site-packages/django/db/models/sql/query.py", line 1559, in build_filter
    condition = self.build_lookup(lookups, col, value)
  File "/home/sf/.local/lib/python3.10/site-packages/django/db/models/sql/query.py", line 1389, in build_lookup
    lookup = lookup_class(lhs, rhs)
  File "/home/sf/.local/lib/python3.10/site-packages/django/db/models/lookups.py", line 30, in __init__
    self.rhs = self.get_prep_lookup()
  File "/home/sf/.local/lib/python3.10/site-packages/django/db/models/lookups.py", line 364, in get_prep_lookup
    return super().get_prep_lookup()
  File "/home/sf/.local/lib/python3.10/site-packages/django/db/models/lookups.py", line 88, in get_prep_lookup
    return self.lhs.output_field.get_prep_value(self.rhs)
  File "/home/sf/.local/lib/python3.10/site-packages/django/db/models/fields/__init__.py", line 2119, in get_prep_value
    raise e.__class__(
TypeError: Field 'round' expected a number but got <built-in function round>.
ERROR 2024-03-30 08:51:32,999 log Internal Server Error: /manage/get_action_tries/세종대/
Traceback (most recent call last):
  File "/home/sf/.local/lib/python3.10/site-packages/django/db/models/fields/__init__.py", line 2117, in get_prep_value
    return int(value)
TypeError: int() argument must be a string, a bytes-like object or a real number, not 'builtin_function_or_method'

The above exception was the direct cause of the following exception:

Traceback (most recent call last):
  File "/home/sf/.local/lib/python3.10/site-packages/asgiref/sync.py", line 534, in thread_handler
    raise exc_info[1]
  File "/home/sf/.local/lib/python3.10/site-packages/django/core/handlers/exception.py", line 42, in inner
    response = await get_response(request)
  File "/home/sf/.local/lib/python3.10/site-packages/django/core/handlers/base.py", line 253, in _get_response_async
    response = await wrapped_callback(
  File "/home/sf/.local/lib/python3.10/site-packages/asgiref/sync.py", line 479, in __call__
    ret: _R = await loop.run_in_executor(
  File "/home/sf/.local/lib/python3.10/site-packages/asgiref/current_thread_executor.py", line 40, in run
    result = self.fn(*self.args, **self.kwargs)
  File "/home/sf/.local/lib/python3.10/site-packages/asgiref/sync.py", line 538, in thread_handler
    return func(*args, **kwargs)
  File "/home/sf/sang/Fortuna/FortunaProject/./flag/views.py", line 149, in get_action_tries_for_team
    action_tries = ActionTry.objects.filter(attacker_name=team_name, round=round)
  File "/home/sf/.local/lib/python3.10/site-packages/django/db/models/manager.py", line 87, in manager_method
    return getattr(self.get_queryset(), name)(*args, **kwargs)
  File "/home/sf/.local/lib/python3.10/site-packages/django/db/models/query.py", line 1476, in filter
    return self._filter_or_exclude(False, args, kwargs)
  File "/home/sf/.local/lib/python3.10/site-packages/django/db/models/query.py", line 1494, in _filter_or_exclude
    clone._filter_or_exclude_inplace(negate, args, kwargs)
  File "/home/sf/.local/lib/python3.10/site-packages/django/db/models/query.py", line 1501, in _filter_or_exclude_inplace
    self._query.add_q(Q(*args, **kwargs))
  File "/home/sf/.local/lib/python3.10/site-packages/django/db/models/sql/query.py", line 1613, in add_q
    clause, _ = self._add_q(q_object, self.used_aliases)
  File "/home/sf/.local/lib/python3.10/site-packages/django/db/models/sql/query.py", line 1645, in _add_q
    child_clause, needed_inner = self.build_filter(
  File "/home/sf/.local/lib/python3.10/site-packages/django/db/models/sql/query.py", line 1559, in build_filter
    condition = self.build_lookup(lookups, col, value)
  File "/home/sf/.local/lib/python3.10/site-packages/django/db/models/sql/query.py", line 1389, in build_lookup
    lookup = lookup_class(lhs, rhs)
  File "/home/sf/.local/lib/python3.10/site-packages/django/db/models/lookups.py", line 30, in __init__
    self.rhs = self.get_prep_lookup()
  File "/home/sf/.local/lib/python3.10/site-packages/django/db/models/lookups.py", line 364, in get_prep_lookup
    return super().get_prep_lookup()
  File "/home/sf/.local/lib/python3.10/site-packages/django/db/models/lookups.py", line 88, in get_prep_lookup
    return self.lhs.output_field.get_prep_value(self.rhs)
  File "/home/sf/.local/lib/python3.10/site-packages/django/db/models/fields/__init__.py", line 2119, in get_prep_value
    raise e.__class__(
TypeError: Field 'round' expected a number but got <built-in function round>.
ERROR 2024-03-30 08:52:08,289 log Internal Server Error: /manage/flag/create_flag/
Traceback (most recent call last):
  File "/home/sf/.local/lib/python3.10/site-packages/asgiref/sync.py", line 534, in thread_handler
    raise exc_info[1]
  File "/home/sf/.local/lib/python3.10/site-packages/django/core/handlers/exception.py", line 42, in inner
    response = await get_response(request)
  File "/home/sf/.local/lib/python3.10/site-packages/django/core/handlers/base.py", line 253, in _get_response_async
    response = await wrapped_callback(
  File "/home/sf/.local/lib/python3.10/site-packages/asgiref/sync.py", line 479, in __call__
    ret: _R = await loop.run_in_executor(
  File "/home/sf/.local/lib/python3.10/site-packages/asgiref/current_thread_executor.py", line 40, in run
    result = self.fn(*self.args, **self.kwargs)
  File "/home/sf/.local/lib/python3.10/site-packages/asgiref/sync.py", line 538, in thread_handler
    return func(*args, **kwargs)
  File "/home/sf/sang/Fortuna/FortunaProject/./flag/views.py", line 129, in create_flag_view
    create_flag()  # 플래그 생성
  File "/home/sf/sang/Fortuna/FortunaProject/./flag/views.py", line 121, in create_flag
    flags_created = generate_flag_for_gamebox(gamebox.team_id, gamebox.challenge_id)
  File "/home/sf/sang/Fortuna/FortunaProject/./flag/views.py", line 82, in generate_flag_for_gamebox
    team = Team.objects.get(team_id=team_id)
  File "/home/sf/.local/lib/python3.10/site-packages/django/db/models/manager.py", line 87, in manager_method
    return getattr(self.get_queryset(), name)(*args, **kwargs)
  File "/home/sf/.local/lib/python3.10/site-packages/django/db/models/query.py", line 649, in get
    raise self.model.DoesNotExist(
account.models.Team.DoesNotExist: Team matching query does not exist.
ERROR 2024-03-30 09:02:07,039 log Internal Server Error: /manage/get_action_tries/세종대/
Traceback (most recent call last):
  File "/home/sf/.local/lib/python3.10/site-packages/django/db/models/fields/__init__.py", line 2117, in get_prep_value
    return int(value)
TypeError: int() argument must be a string, a bytes-like object or a real number, not 'builtin_function_or_method'

The above exception was the direct cause of the following exception:

Traceback (most recent call last):
  File "/home/sf/.local/lib/python3.10/site-packages/asgiref/sync.py", line 534, in thread_handler
    raise exc_info[1]
  File "/home/sf/.local/lib/python3.10/site-packages/django/core/handlers/exception.py", line 42, in inner
    response = await get_response(request)
  File "/home/sf/.local/lib/python3.10/site-packages/django/core/handlers/base.py", line 253, in _get_response_async
    response = await wrapped_callback(
  File "/home/sf/.local/lib/python3.10/site-packages/asgiref/sync.py", line 479, in __call__
    ret: _R = await loop.run_in_executor(
  File "/home/sf/.local/lib/python3.10/site-packages/asgiref/current_thread_executor.py", line 40, in run
    result = self.fn(*self.args, **self.kwargs)
  File "/home/sf/.local/lib/python3.10/site-packages/asgiref/sync.py", line 538, in thread_handler
    return func(*args, **kwargs)
  File "/home/sf/sang/Fortuna/FortunaProject/./flag/views.py", line 149, in get_action_tries_for_team
    action_tries = ActionTry.objects.filter(attacker_name=team_name, round=round)
  File "/home/sf/.local/lib/python3.10/site-packages/django/db/models/manager.py", line 87, in manager_method
    return getattr(self.get_queryset(), name)(*args, **kwargs)
  File "/home/sf/.local/lib/python3.10/site-packages/django/db/models/query.py", line 1476, in filter
    return self._filter_or_exclude(False, args, kwargs)
  File "/home/sf/.local/lib/python3.10/site-packages/django/db/models/query.py", line 1494, in _filter_or_exclude
    clone._filter_or_exclude_inplace(negate, args, kwargs)
  File "/home/sf/.local/lib/python3.10/site-packages/django/db/models/query.py", line 1501, in _filter_or_exclude_inplace
    self._query.add_q(Q(*args, **kwargs))
  File "/home/sf/.local/lib/python3.10/site-packages/django/db/models/sql/query.py", line 1613, in add_q
    clause, _ = self._add_q(q_object, self.used_aliases)
  File "/home/sf/.local/lib/python3.10/site-packages/django/db/models/sql/query.py", line 1645, in _add_q
    child_clause, needed_inner = self.build_filter(
  File "/home/sf/.local/lib/python3.10/site-packages/django/db/models/sql/query.py", line 1559, in build_filter
    condition = self.build_lookup(lookups, col, value)
  File "/home/sf/.local/lib/python3.10/site-packages/django/db/models/sql/query.py", line 1389, in build_lookup
    lookup = lookup_class(lhs, rhs)
  File "/home/sf/.local/lib/python3.10/site-packages/django/db/models/lookups.py", line 30, in __init__
    self.rhs = self.get_prep_lookup()
  File "/home/sf/.local/lib/python3.10/site-packages/django/db/models/lookups.py", line 364, in get_prep_lookup
    return super().get_prep_lookup()
  File "/home/sf/.local/lib/python3.10/site-packages/django/db/models/lookups.py", line 88, in get_prep_lookup
    return self.lhs.output_field.get_prep_value(self.rhs)
  File "/home/sf/.local/lib/python3.10/site-packages/django/db/models/fields/__init__.py", line 2119, in get_prep_value
    raise e.__class__(
TypeError: Field 'round' expected a number but got <built-in function round>.
ERROR 2024-03-30 09:10:51,049 log Internal Server Error: /manage/get_action_tries/admin/
Traceback (most recent call last):
  File "/home/sf/.local/lib/python3.10/site-packages/django/db/models/fields/__init__.py", line 2117, in get_prep_value
    return int(value)
TypeError: int() argument must be a string, a bytes-like object or a real number, not 'builtin_function_or_method'

The above exception was the direct cause of the following exception:

Traceback (most recent call last):
  File "/home/sf/.local/lib/python3.10/site-packages/asgiref/sync.py", line 534, in thread_handler
    raise exc_info[1]
  File "/home/sf/.local/lib/python3.10/site-packages/django/core/handlers/exception.py", line 42, in inner
    response = await get_response(request)
  File "/home/sf/.local/lib/python3.10/site-packages/django/core/handlers/base.py", line 253, in _get_response_async
    response = await wrapped_callback(
  File "/home/sf/.local/lib/python3.10/site-packages/asgiref/sync.py", line 479, in __call__
    ret: _R = await loop.run_in_executor(
  File "/home/sf/.local/lib/python3.10/site-packages/asgiref/current_thread_executor.py", line 40, in run
    result = self.fn(*self.args, **self.kwargs)
  File "/home/sf/.local/lib/python3.10/site-packages/asgiref/sync.py", line 538, in thread_handler
    return func(*args, **kwargs)
  File "/home/sf/sang/Fortuna/FortunaProject/./flag/views.py", line 149, in get_action_tries_for_team
    action_tries = ActionTry.objects.filter(attacker_name=team_name, round=round)
  File "/home/sf/.local/lib/python3.10/site-packages/django/db/models/manager.py", line 87, in manager_method
    return getattr(self.get_queryset(), name)(*args, **kwargs)
  File "/home/sf/.local/lib/python3.10/site-packages/django/db/models/query.py", line 1476, in filter
    return self._filter_or_exclude(False, args, kwargs)
  File "/home/sf/.local/lib/python3.10/site-packages/django/db/models/query.py", line 1494, in _filter_or_exclude
    clone._filter_or_exclude_inplace(negate, args, kwargs)
  File "/home/sf/.local/lib/python3.10/site-packages/django/db/models/query.py", line 1501, in _filter_or_exclude_inplace
    self._query.add_q(Q(*args, **kwargs))
  File "/home/sf/.local/lib/python3.10/site-packages/django/db/models/sql/query.py", line 1613, in add_q
    clause, _ = self._add_q(q_object, self.used_aliases)
  File "/home/sf/.local/lib/python3.10/site-packages/django/db/models/sql/query.py", line 1645, in _add_q
    child_clause, needed_inner = self.build_filter(
  File "/home/sf/.local/lib/python3.10/site-packages/django/db/models/sql/query.py", line 1559, in build_filter
    condition = self.build_lookup(lookups, col, value)
  File "/home/sf/.local/lib/python3.10/site-packages/django/db/models/sql/query.py", line 1389, in build_lookup
    lookup = lookup_class(lhs, rhs)
  File "/home/sf/.local/lib/python3.10/site-packages/django/db/models/lookups.py", line 30, in __init__
    self.rhs = self.get_prep_lookup()
  File "/home/sf/.local/lib/python3.10/site-packages/django/db/models/lookups.py", line 364, in get_prep_lookup
    return super().get_prep_lookup()
  File "/home/sf/.local/lib/python3.10/site-packages/django/db/models/lookups.py", line 88, in get_prep_lookup
    return self.lhs.output_field.get_prep_value(self.rhs)
  File "/home/sf/.local/lib/python3.10/site-packages/django/db/models/fields/__init__.py", line 2119, in get_prep_value
    raise e.__class__(
TypeError: Field 'round' expected a number but got <built-in function round>.
ERROR 2024-03-30 09:11:19,920 log Internal Server Error: /manage/get_action_tries/세종대/
Traceback (most recent call last):
  File "/home/sf/.local/lib/python3.10/site-packages/django/db/models/fields/__init__.py", line 2117, in get_prep_value
    return int(value)
TypeError: int() argument must be a string, a bytes-like object or a real number, not 'builtin_function_or_method'

The above exception was the direct cause of the following exception:

Traceback (most recent call last):
  File "/home/sf/.local/lib/python3.10/site-packages/asgiref/sync.py", line 534, in thread_handler
    raise exc_info[1]
  File "/home/sf/.local/lib/python3.10/site-packages/django/core/handlers/exception.py", line 42, in inner
    response = await get_response(request)
  File "/home/sf/.local/lib/python3.10/site-packages/django/core/handlers/base.py", line 253, in _get_response_async
    response = await wrapped_callback(
  File "/home/sf/.local/lib/python3.10/site-packages/asgiref/sync.py", line 479, in __call__
    ret: _R = await loop.run_in_executor(
  File "/home/sf/.local/lib/python3.10/site-packages/asgiref/current_thread_executor.py", line 40, in run
    result = self.fn(*self.args, **self.kwargs)
  File "/home/sf/.local/lib/python3.10/site-packages/asgiref/sync.py", line 538, in thread_handler
    return func(*args, **kwargs)
  File "/home/sf/sang/Fortuna/FortunaProject/./flag/views.py", line 149, in get_action_tries_for_team
    action_tries = ActionTry.objects.filter(attacker_name=team_name, round=round)
  File "/home/sf/.local/lib/python3.10/site-packages/django/db/models/manager.py", line 87, in manager_method
    return getattr(self.get_queryset(), name)(*args, **kwargs)
  File "/home/sf/.local/lib/python3.10/site-packages/django/db/models/query.py", line 1476, in filter
    return self._filter_or_exclude(False, args, kwargs)
  File "/home/sf/.local/lib/python3.10/site-packages/django/db/models/query.py", line 1494, in _filter_or_exclude
    clone._filter_or_exclude_inplace(negate, args, kwargs)
  File "/home/sf/.local/lib/python3.10/site-packages/django/db/models/query.py", line 1501, in _filter_or_exclude_inplace
    self._query.add_q(Q(*args, **kwargs))
  File "/home/sf/.local/lib/python3.10/site-packages/django/db/models/sql/query.py", line 1613, in add_q
    clause, _ = self._add_q(q_object, self.used_aliases)
  File "/home/sf/.local/lib/python3.10/site-packages/django/db/models/sql/query.py", line 1645, in _add_q
    child_clause, needed_inner = self.build_filter(
  File "/home/sf/.local/lib/python3.10/site-packages/django/db/models/sql/query.py", line 1559, in build_filter
    condition = self.build_lookup(lookups, col, value)
  File "/home/sf/.local/lib/python3.10/site-packages/django/db/models/sql/query.py", line 1389, in build_lookup
    lookup = lookup_class(lhs, rhs)
  File "/home/sf/.local/lib/python3.10/site-packages/django/db/models/lookups.py", line 30, in __init__
    self.rhs = self.get_prep_lookup()
  File "/home/sf/.local/lib/python3.10/site-packages/django/db/models/lookups.py", line 364, in get_prep_lookup
    return super().get_prep_lookup()
  File "/home/sf/.local/lib/python3.10/site-packages/django/db/models/lookups.py", line 88, in get_prep_lookup
    return self.lhs.output_field.get_prep_value(self.rhs)
  File "/home/sf/.local/lib/python3.10/site-packages/django/db/models/fields/__init__.py", line 2119, in get_prep_value
    raise e.__class__(
TypeError: Field 'round' expected a number but got <built-in function round>.
ERROR 2024-03-30 09:17:14,557 log Internal Server Error: /manage/get_action_tries/세종대/
Traceback (most recent call last):
  File "/home/sf/.local/lib/python3.10/site-packages/django/db/models/fields/__init__.py", line 2117, in get_prep_value
    return int(value)
TypeError: int() argument must be a string, a bytes-like object or a real number, not 'builtin_function_or_method'

The above exception was the direct cause of the following exception:

Traceback (most recent call last):
  File "/home/sf/.local/lib/python3.10/site-packages/asgiref/sync.py", line 534, in thread_handler
    raise exc_info[1]
  File "/home/sf/.local/lib/python3.10/site-packages/django/core/handlers/exception.py", line 42, in inner
    response = await get_response(request)
  File "/home/sf/.local/lib/python3.10/site-packages/django/core/handlers/base.py", line 253, in _get_response_async
    response = await wrapped_callback(
  File "/home/sf/.local/lib/python3.10/site-packages/asgiref/sync.py", line 479, in __call__
    ret: _R = await loop.run_in_executor(
  File "/home/sf/.local/lib/python3.10/site-packages/asgiref/current_thread_executor.py", line 40, in run
    result = self.fn(*self.args, **self.kwargs)
  File "/home/sf/.local/lib/python3.10/site-packages/asgiref/sync.py", line 538, in thread_handler
    return func(*args, **kwargs)
  File "/home/sf/sang/Fortuna/FortunaProject/./flag/views.py", line 149, in get_action_tries_for_team
    action_tries = ActionTry.objects.filter(attacker_name=team_name, round=round)
  File "/home/sf/.local/lib/python3.10/site-packages/django/db/models/manager.py", line 87, in manager_method
    return getattr(self.get_queryset(), name)(*args, **kwargs)
  File "/home/sf/.local/lib/python3.10/site-packages/django/db/models/query.py", line 1476, in filter
    return self._filter_or_exclude(False, args, kwargs)
  File "/home/sf/.local/lib/python3.10/site-packages/django/db/models/query.py", line 1494, in _filter_or_exclude
    clone._filter_or_exclude_inplace(negate, args, kwargs)
  File "/home/sf/.local/lib/python3.10/site-packages/django/db/models/query.py", line 1501, in _filter_or_exclude_inplace
    self._query.add_q(Q(*args, **kwargs))
  File "/home/sf/.local/lib/python3.10/site-packages/django/db/models/sql/query.py", line 1613, in add_q
    clause, _ = self._add_q(q_object, self.used_aliases)
  File "/home/sf/.local/lib/python3.10/site-packages/django/db/models/sql/query.py", line 1645, in _add_q
    child_clause, needed_inner = self.build_filter(
  File "/home/sf/.local/lib/python3.10/site-packages/django/db/models/sql/query.py", line 1559, in build_filter
    condition = self.build_lookup(lookups, col, value)
  File "/home/sf/.local/lib/python3.10/site-packages/django/db/models/sql/query.py", line 1389, in build_lookup
    lookup = lookup_class(lhs, rhs)
  File "/home/sf/.local/lib/python3.10/site-packages/django/db/models/lookups.py", line 30, in __init__
    self.rhs = self.get_prep_lookup()
  File "/home/sf/.local/lib/python3.10/site-packages/django/db/models/lookups.py", line 364, in get_prep_lookup
    return super().get_prep_lookup()
  File "/home/sf/.local/lib/python3.10/site-packages/django/db/models/lookups.py", line 88, in get_prep_lookup
    return self.lhs.output_field.get_prep_value(self.rhs)
  File "/home/sf/.local/lib/python3.10/site-packages/django/db/models/fields/__init__.py", line 2119, in get_prep_value
    raise e.__class__(
TypeError: Field 'round' expected a number but got <built-in function round>.
ERROR 2024-03-30 09:24:29,320 log Internal Server Error: /manage/get_action_tries/세종대/
Traceback (most recent call last):
  File "/home/sf/.local/lib/python3.10/site-packages/django/db/models/fields/__init__.py", line 2117, in get_prep_value
    return int(value)
TypeError: int() argument must be a string, a bytes-like object or a real number, not 'builtin_function_or_method'

The above exception was the direct cause of the following exception:

Traceback (most recent call last):
  File "/home/sf/.local/lib/python3.10/site-packages/asgiref/sync.py", line 534, in thread_handler
    raise exc_info[1]
  File "/home/sf/.local/lib/python3.10/site-packages/django/core/handlers/exception.py", line 42, in inner
    response = await get_response(request)
  File "/home/sf/.local/lib/python3.10/site-packages/django/core/handlers/base.py", line 253, in _get_response_async
    response = await wrapped_callback(
  File "/home/sf/.local/lib/python3.10/site-packages/asgiref/sync.py", line 479, in __call__
    ret: _R = await loop.run_in_executor(
  File "/home/sf/.local/lib/python3.10/site-packages/asgiref/current_thread_executor.py", line 40, in run
    result = self.fn(*self.args, **self.kwargs)
  File "/home/sf/.local/lib/python3.10/site-packages/asgiref/sync.py", line 538, in thread_handler
    return func(*args, **kwargs)
  File "/home/sf/sang/Fortuna/FortunaProject/./flag/views.py", line 149, in get_action_tries_for_team
    action_tries = ActionTry.objects.filter(attacker_name=team_name, round=round)
  File "/home/sf/.local/lib/python3.10/site-packages/django/db/models/manager.py", line 87, in manager_method
    return getattr(self.get_queryset(), name)(*args, **kwargs)
  File "/home/sf/.local/lib/python3.10/site-packages/django/db/models/query.py", line 1476, in filter
    return self._filter_or_exclude(False, args, kwargs)
  File "/home/sf/.local/lib/python3.10/site-packages/django/db/models/query.py", line 1494, in _filter_or_exclude
    clone._filter_or_exclude_inplace(negate, args, kwargs)
  File "/home/sf/.local/lib/python3.10/site-packages/django/db/models/query.py", line 1501, in _filter_or_exclude_inplace
    self._query.add_q(Q(*args, **kwargs))
  File "/home/sf/.local/lib/python3.10/site-packages/django/db/models/sql/query.py", line 1613, in add_q
    clause, _ = self._add_q(q_object, self.used_aliases)
  File "/home/sf/.local/lib/python3.10/site-packages/django/db/models/sql/query.py", line 1645, in _add_q
    child_clause, needed_inner = self.build_filter(
  File "/home/sf/.local/lib/python3.10/site-packages/django/db/models/sql/query.py", line 1559, in build_filter
    condition = self.build_lookup(lookups, col, value)
  File "/home/sf/.local/lib/python3.10/site-packages/django/db/models/sql/query.py", line 1389, in build_lookup
    lookup = lookup_class(lhs, rhs)
  File "/home/sf/.local/lib/python3.10/site-packages/django/db/models/lookups.py", line 30, in __init__
    self.rhs = self.get_prep_lookup()
  File "/home/sf/.local/lib/python3.10/site-packages/django/db/models/lookups.py", line 364, in get_prep_lookup
    return super().get_prep_lookup()
  File "/home/sf/.local/lib/python3.10/site-packages/django/db/models/lookups.py", line 88, in get_prep_lookup
    return self.lhs.output_field.get_prep_value(self.rhs)
  File "/home/sf/.local/lib/python3.10/site-packages/django/db/models/fields/__init__.py", line 2119, in get_prep_value
    raise e.__class__(
TypeError: Field 'round' expected a number but got <built-in function round>.
