ERROR 2024-02-20 14:59:00,045 log Internal Server Error: /manage/dashboard/
Traceback (most recent call last):
  File "/usr/lib/python3/dist-packages/asgiref/sync.py", line 451, in thread_handler
    raise exc_info[1]
  File "/usr/lib/python3/dist-packages/django/core/handlers/exception.py", line 38, in inner
    response = await get_response(request)
  File "/usr/lib/python3/dist-packages/django/core/handlers/base.py", line 233, in _get_response_async
    response = await wrapped_callback(request, *callback_args, **callback_kwargs)
  File "/usr/lib/python3/dist-packages/asgiref/sync.py", line 414, in __call__
    ret = await asyncio.wait_for(future, timeout=None)
  File "/usr/lib/python3.10/asyncio/tasks.py", line 408, in wait_for
    return await fut
  File "/usr/lib/python3/dist-packages/asgiref/current_thread_executor.py", line 22, in run
    result = self.fn(*self.args, **self.kwargs)
  File "/usr/lib/python3/dist-packages/asgiref/sync.py", line 455, in thread_handler
    return func(*args, **kwargs)
  File "/home/qwer/Fortuna/FortunaProject/./manage/views.py", line 55, in dashboard_view
    return render(request, 'manage/dashboard.html', context)
  File "/usr/lib/python3/dist-packages/django/shortcuts.py", line 19, in render
    content = loader.render_to_string(template_name, context, request, using=using)
  File "/usr/lib/python3/dist-packages/django/template/loader.py", line 61, in render_to_string
    template = get_template(template_name, using=using)
  File "/usr/lib/python3/dist-packages/django/template/loader.py", line 15, in get_template
    return engine.get_template(template_name)
  File "/usr/lib/python3/dist-packages/django/template/backends/django.py", line 34, in get_template
    return Template(self.engine.get_template(template_name), self)
  File "/usr/lib/python3/dist-packages/django/template/engine.py", line 143, in get_template
    template, origin = self.find_template(template_name)
  File "/usr/lib/python3/dist-packages/django/template/engine.py", line 125, in find_template
    template = loader.get_template(name, skip=skip)
  File "/usr/lib/python3/dist-packages/django/template/loaders/base.py", line 29, in get_template
    return Template(
  File "/usr/lib/python3/dist-packages/django/template/base.py", line 155, in __init__
    self.nodelist = self.compile_nodelist()
  File "/usr/lib/python3/dist-packages/django/template/base.py", line 193, in compile_nodelist
    return parser.parse()
  File "/usr/lib/python3/dist-packages/django/template/base.py", line 478, in parse
    raise self.error(token, e)
  File "/usr/lib/python3/dist-packages/django/template/base.py", line 476, in parse
    compiled_result = compile_func(self, token)
  File "/usr/lib/python3/dist-packages/django/template/loader_tags.py", line 278, in do_extends
    nodelist = parser.parse()
  File "/usr/lib/python3/dist-packages/django/template/base.py", line 478, in parse
    raise self.error(token, e)
  File "/usr/lib/python3/dist-packages/django/template/base.py", line 476, in parse
    compiled_result = compile_func(self, token)
  File "/usr/lib/python3/dist-packages/django/template/loader_tags.py", line 216, in do_block
    nodelist = parser.parse(('endblock',))
  File "/usr/lib/python3/dist-packages/django/template/base.py", line 478, in parse
    raise self.error(token, e)
  File "/usr/lib/python3/dist-packages/django/template/base.py", line 476, in parse
    compiled_result = compile_func(self, token)
  File "/usr/lib/python3/dist-packages/django/template/defaulttags.py", line 817, in do_for
    nodelist_loop = parser.parse(('empty', 'endfor',))
  File "/usr/lib/python3/dist-packages/django/template/base.py", line 478, in parse
    raise self.error(token, e)
  File "/usr/lib/python3/dist-packages/django/template/base.py", line 476, in parse
    compiled_result = compile_func(self, token)
  File "/usr/lib/python3/dist-packages/django/template/defaulttags.py", line 817, in do_for
    nodelist_loop = parser.parse(('empty', 'endfor',))
  File "/usr/lib/python3/dist-packages/django/template/base.py", line 449, in parse
    raise self.error(token, e)
  File "/usr/lib/python3/dist-packages/django/template/base.py", line 447, in parse
    filter_expression = self.compile_filter(token.contents)
  File "/usr/lib/python3/dist-packages/django/template/base.py", line 563, in compile_filter
    return FilterExpression(token, self)
  File "/usr/lib/python3/dist-packages/django/template/base.py", line 662, in __init__
    raise TemplateSyntaxError("Could not parse the remainder: '%s' "
django.template.exceptions.TemplateSyntaxError: Could not parse the remainder: ' if status == 'o' else 'status-inactive'' from ''status-active' if status == 'o' else 'status-inactive''
ERROR 2024-02-20 15:02:24,236 log Internal Server Error: /manage/dashboard/
Traceback (most recent call last):
  File "/usr/lib/python3/dist-packages/asgiref/sync.py", line 451, in thread_handler
    raise exc_info[1]
  File "/usr/lib/python3/dist-packages/django/core/handlers/exception.py", line 38, in inner
    response = await get_response(request)
  File "/usr/lib/python3/dist-packages/django/core/handlers/base.py", line 233, in _get_response_async
    response = await wrapped_callback(request, *callback_args, **callback_kwargs)
  File "/usr/lib/python3/dist-packages/asgiref/sync.py", line 414, in __call__
    ret = await asyncio.wait_for(future, timeout=None)
  File "/usr/lib/python3.10/asyncio/tasks.py", line 408, in wait_for
    return await fut
  File "/usr/lib/python3/dist-packages/asgiref/current_thread_executor.py", line 22, in run
    result = self.fn(*self.args, **self.kwargs)
  File "/usr/lib/python3/dist-packages/asgiref/sync.py", line 455, in thread_handler
    return func(*args, **kwargs)
  File "/home/qwer/Fortuna/FortunaProject/./manage/views.py", line 44, in dashboard_view
    log_file_path = os.path.join('path_to_your_log_directory', 'django.log')
NameError: name 'os' is not defined
ERROR 2024-02-20 15:02:42,801 log Internal Server Error: /manage/dashboard/
Traceback (most recent call last):
  File "/usr/lib/python3/dist-packages/asgiref/sync.py", line 451, in thread_handler
    raise exc_info[1]
  File "/usr/lib/python3/dist-packages/django/core/handlers/exception.py", line 38, in inner
    response = await get_response(request)
  File "/usr/lib/python3/dist-packages/django/core/handlers/base.py", line 233, in _get_response_async
    response = await wrapped_callback(request, *callback_args, **callback_kwargs)
  File "/usr/lib/python3/dist-packages/asgiref/sync.py", line 414, in __call__
    ret = await asyncio.wait_for(future, timeout=None)
  File "/usr/lib/python3.10/asyncio/tasks.py", line 408, in wait_for
    return await fut
  File "/usr/lib/python3/dist-packages/asgiref/current_thread_executor.py", line 22, in run
    result = self.fn(*self.args, **self.kwargs)
  File "/usr/lib/python3/dist-packages/asgiref/sync.py", line 455, in thread_handler
    return func(*args, **kwargs)
  File "/home/qwer/Fortuna/FortunaProject/./manage/views.py", line 62, in dashboard_view
    return render(request, 'dashboard.html', context)
  File "/usr/lib/python3/dist-packages/django/shortcuts.py", line 19, in render
    content = loader.render_to_string(template_name, context, request, using=using)
  File "/usr/lib/python3/dist-packages/django/template/loader.py", line 61, in render_to_string
    template = get_template(template_name, using=using)
  File "/usr/lib/python3/dist-packages/django/template/loader.py", line 19, in get_template
    raise TemplateDoesNotExist(template_name, chain=chain)
django.template.exceptions.TemplateDoesNotExist: dashboard.html
ERROR 2024-02-20 15:03:26,659 log Internal Server Error: /manage/dashboard/
Traceback (most recent call last):
  File "/usr/lib/python3/dist-packages/asgiref/sync.py", line 451, in thread_handler
    raise exc_info[1]
  File "/usr/lib/python3/dist-packages/django/core/handlers/exception.py", line 38, in inner
    response = await get_response(request)
  File "/usr/lib/python3/dist-packages/django/core/handlers/base.py", line 233, in _get_response_async
    response = await wrapped_callback(request, *callback_args, **callback_kwargs)
  File "/usr/lib/python3/dist-packages/asgiref/sync.py", line 414, in __call__
    ret = await asyncio.wait_for(future, timeout=None)
  File "/usr/lib/python3.10/asyncio/tasks.py", line 408, in wait_for
    return await fut
  File "/usr/lib/python3/dist-packages/asgiref/current_thread_executor.py", line 22, in run
    result = self.fn(*self.args, **self.kwargs)
  File "/usr/lib/python3/dist-packages/asgiref/sync.py", line 455, in thread_handler
    return func(*args, **kwargs)
  File "/home/qwer/Fortuna/FortunaProject/./manage/views.py", line 62, in dashboard_view
    return render(request, 'manage/dashboard.html', context)
  File "/usr/lib/python3/dist-packages/django/shortcuts.py", line 19, in render
    content = loader.render_to_string(template_name, context, request, using=using)
  File "/usr/lib/python3/dist-packages/django/template/loader.py", line 61, in render_to_string
    template = get_template(template_name, using=using)
  File "/usr/lib/python3/dist-packages/django/template/loader.py", line 19, in get_template
    raise TemplateDoesNotExist(template_name, chain=chain)
django.template.exceptions.TemplateDoesNotExist: dashboard.html
ERROR 2024-02-20 15:17:41,636 log Internal Server Error: /manage/dashboard/
Traceback (most recent call last):
  File "/usr/lib/python3/dist-packages/asgiref/sync.py", line 451, in thread_handler
    raise exc_info[1]
  File "/usr/lib/python3/dist-packages/django/core/handlers/exception.py", line 38, in inner
    response = await get_response(request)
  File "/usr/lib/python3/dist-packages/django/core/handlers/base.py", line 233, in _get_response_async
    response = await wrapped_callback(request, *callback_args, **callback_kwargs)
  File "/usr/lib/python3/dist-packages/asgiref/sync.py", line 414, in __call__
    ret = await asyncio.wait_for(future, timeout=None)
  File "/usr/lib/python3.10/asyncio/tasks.py", line 408, in wait_for
    return await fut
  File "/usr/lib/python3/dist-packages/asgiref/current_thread_executor.py", line 22, in run
    result = self.fn(*self.args, **self.kwargs)
  File "/usr/lib/python3/dist-packages/asgiref/sync.py", line 455, in thread_handler
    return func(*args, **kwargs)
  File "/home/qwer/Fortuna/FortunaProject/./manage/views.py", line 48, in dashboard_view
    django_log = tail(file, lines=100)  # 마지막 100줄 읽기
  File "/home/qwer/Fortuna/FortunaProject/./manage/views.py", line 78, in tail
    f.seek(block_number*BLOCK_SIZE, 2)
io.UnsupportedOperation: can't do nonzero end-relative seeks
